<?xml version="1.0"?>
<sdf version="1.10">
  <model name="tailsitter">
    <pose>0 0 0.3 0.0 -1.57096 0.5</pose>
    <!-- <pose>0 0 0.3 0 0 0</pose> -->
    <!-- <pose>0 0 0.3 0 -1.57096 -1.1</pose> -->
    <static>0</static>

    <link name="base_link">` <!-- \todo provide proper inertial : actual mass 1.75 kg -->
      <inertial>
        <pose>0 0 0 0 0 0.5</pose>
        <mass>2.0</mass>
        <inertia>
          <ixx>0.043609000000000</ixx>
          <ixy>0</ixy>
          <ixz>0</ixz>
          <iyy>0.04513000000000</iyy>
          <iyz>0</iyz>
          <izz>0.083220000000000</izz>
        </inertia>
      </inertial>
      <collision name="collision">
        <geometry>
          <mesh>
            <uri>model://tailsitter/meshes/tailsitter_fuselage.dae</uri>
          </mesh>
        </geometry>
      </collision>
      <visual
        name="fuselage_visual">
        <geometry>
          <mesh>
            <uri>model://tailsitter/meshes/tailsitter_fuselage.dae</uri>
          </mesh>
        </geometry>
        <material>
          <ambient>1 1 1</ambient>
          <diffuse>1 1 1</diffuse>
          <specular>0.5 0.5 0.5</specular>
          <pbr>
            <metal>
              <albedo_map>model://tailsitter/materials/textures/foxmap.tga</albedo_map>
              <roughness>0.5</roughness>
              <metalness>0.5</metalness>
            </metal>
          </pbr>
        </material>
      </visual>

      <collision
        name="leg1_collision">
        <pose>-0.26 -0.25 -0.32 0 0 0</pose>
        <geometry>
          <sphere>
            <radius>0.01</radius>
          </sphere>
        </geometry>
      </collision>
      <collision
        name="leg2_collision">
        <pose>-0.26 0.25 0.32 0 0 0</pose>
        <geometry>
          <sphere>
            <radius>0.01</radius>
          </sphere>
        </geometry>
      </collision>
      <collision
        name="leg3_collision">
        <pose>-0.26 0.25 -0.32 0 0 0</pose>
        <geometry>
          <sphere>
            <radius>0.01</radius>
          </sphere>
        </geometry>
      </collision>
      <collision
        name="leg4_collision">
        <pose>-0.26 -0.25 0.32 0 0 0</pose>
        <geometry>
          <sphere>
            <radius>0.01</radius>
          </sphere>
        </geometry>
      </collision>

      <sensor
        name="air_pressure_sensor" type="air_pressure">
        <always_on>1</always_on>
        <update_rate>50</update_rate>
        <air_pressure>
          <pressure>
            <noise type="gaussian">
              <mean>0</mean>
              <stddev>0.01</stddev>
            </noise>
          </pressure>
        </air_pressure>
      </sensor>
      <sensor
        name="imu_sensor" type="imu">
        <pose relative_to="base_link">0 0 0 0 0 0</pose>
        <always_on>1</always_on>
        <update_rate>250</update_rate>
        <visualize>true</visualize>
      </sensor>
    </link>

    <!-- https://ardupilot.org/plane/docs/guide-tailsitter.html#nyt-quad-x-motor-tailsitter -->
    <!-- CCW -->
    <link name="rotor_0_link">
      <pose relative_to="rotor_0_joint">0 0 0 0 0 0</pose>
      <inertial>
        <pose>0 0 0 0 0 0</pose>
        <mass>0.025</mass>
        <inertia>
          <ixx>0.000130417</ixx>
          <ixy>0</ixy>
          <ixz>0</ixz>
          <iyy>0.000130417</iyy>
          <iyz>0</iyz>
          <izz>0.000260417</izz>
        </inertia>
      </inertial>
      <collision name="motor_collision">
        <geometry>
          <cylinder>
            <length>0.0178</length>
            <radius>0.0112</radius>
          </cylinder>
        </geometry>
      </collision>
      <collision name="prop_collision">
        <pose>0 0 0.022 0 0 0</pose>
        <geometry>
          <cylinder>
            <length>0.005</length>
            <radius>0.13</radius>
          </cylinder>
        </geometry>
      </collision>

      <visual name="motor_visual">
        <pose>0 0 -0.008 0 -1.5707963 0</pose>
        <geometry>
          <mesh>
            <uri>model://tailsitter/meshes/tailsitter_motor.dae</uri>
          </mesh>
        </geometry>
        <material>
          <ambient>1 1 1</ambient>
          <diffuse>1 1 1</diffuse>
          <specular>1 1 1</specular>
          <pbr>
            <metal>
              <albedo_map>
                model://tailsitter/materials/textures/blue_metal/blue_metal_basecolor.jpg</albedo_map>
              <metalness_map>
                model://tailsitter/materials/textures/blue_metal/blue_metal_metallic.jpg</metalness_map>
              <normal_map>model://tailsitter/materials/textures/blue_metal/blue_metal_normal.jpg</normal_map>
              <roughness_map>
                model://tailsitter/materials/textures/blue_metal/blue_metal_roughness.jpg</roughness_map>
              <roughness>1.0</roughness>
              <metalness>1.0</metalness>
            </metal>
          </pbr>
        </material>
      </visual>
      <visual name='prop_visual'>
        <pose>0 0 0.015 0 0 0</pose>
        <geometry>
          <mesh>
            <scale>1 1 1</scale>
            <uri>model://tailsitter/meshes/iris_prop_ccw.dae</uri>
          </mesh>
        </geometry>
        <material>
          <diffuse>1.0 1.0 1.0</diffuse>
          <specular>1.0 1.0 1.0</specular>
          <pbr>
            <metal>
              <albedo_map>
                model://tailsitter/materials/textures/metal_graphite/metal_graphite_basecolor.jpg</albedo_map>
              <metalness_map>
                model://tailsitter/materials/textures/metal_graphite/metal_graphite_metallic.jpg</metalness_map>
              <normal_map>
                model://tailsitter/materials/textures/metal_graphite/metal_graphite_normal.jpg</normal_map>
              <roughness_map>
                model://tailsitter/materials/textures/metal_graphite/metal_graphite_roughness.jpg</roughness_map>
              <roughness>1.0</roughness>
              <metalness>1.0</metalness>
            </metal>
          </pbr>
        </material>
      </visual>
    </link>
    <joint name='rotor_0_joint' type='revolute'>
      <!-- <pose relative_to="base_link">-0.015 -0.25 -0.32 0.174532925 1.396263402 0</pose> -->
      <pose relative_to="base_link">-0.015 -0.32 -0.32 0 1.5708 0</pose>
      <child>rotor_0_link</child>
      <parent>base_link</parent>
      <axis>
        <xyz>0 0 1</xyz>
        <limit>
          <lower>-1e+16</lower>
          <upper>1e+16</upper>
        </limit>
        <dynamics>
          <damping>0.004</damping>
        </dynamics>
      </axis>
    </joint>

    <!-- CCW -->
    <link name="rotor_1_link">
      <pose relative_to="rotor_1_joint">0 0 0 0 0 0</pose>
      <inertial>
        <pose>0 0 0 0 0 0</pose>
        <mass>0.025</mass>
        <inertia>
          <ixx>0.000130417</ixx>
          <ixy>0</ixy>
          <ixz>0</ixz>
          <iyy>0.000130417</iyy>
          <iyz>0</iyz>
          <izz>0.000260417</izz>
        </inertia>
      </inertial>
      <collision name="motor_collision">
        <geometry>
          <cylinder>
            <length>0.0178</length>
            <radius>0.0112</radius>
          </cylinder>
        </geometry>
      </collision>
      <collision name="prop_collision">
        <pose>0 0 0.022 0 0 0</pose>
        <geometry>
          <cylinder>
            <length>0.005</length>
            <radius>0.13</radius>
          </cylinder>
        </geometry>
      </collision>
      <visual name="motor_visual">
        <pose>0 0 -0.008 0 -1.5707963 0</pose>
        <geometry>
          <mesh>
            <uri>model://tailsitter/meshes/tailsitter_motor.dae</uri>
          </mesh>
        </geometry>
        <material>
          <ambient>1 1 1</ambient>
          <diffuse>1 1 1</diffuse>
          <specular>1 1 1</specular>
          <pbr>
            <metal>
              <albedo_map>
                model://tailsitter/materials/textures/blue_metal/blue_metal_basecolor.jpg</albedo_map>
              <metalness_map>
                model://tailsitter/materials/textures/blue_metal/blue_metal_metallic.jpg</metalness_map>
              <normal_map>model://tailsitter/materials/textures/blue_metal/blue_metal_normal.jpg</normal_map>
              <roughness_map>
                model://tailsitter/materials/textures/blue_metal/blue_metal_roughness.jpg</roughness_map>
              <roughness>1.0</roughness>
              <metalness>1.0</metalness>
            </metal>
          </pbr>
        </material>
      </visual>
      <visual name='prop_visual'>
        <pose>0 0 0.015 0 0 0</pose>
        <geometry>
          <mesh>
            <scale>1 1 1</scale>
            <uri>model://tailsitter/meshes/iris_prop_ccw.dae</uri>
          </mesh>
        </geometry>
        <material>
          <diffuse>1.0 1.0 1.0</diffuse>
          <specular>1.0 1.0 1.0</specular>
          <pbr>
            <metal>
              <albedo_map>
                model://tailsitter/materials/textures/metal_graphite/metal_graphite_basecolor.jpg</albedo_map>
              <metalness_map>
                model://tailsitter/materials/textures/metal_graphite/metal_graphite_metallic.jpg</metalness_map>
              <normal_map>
                model://tailsitter/materials/textures/metal_graphite/metal_graphite_normal.jpg</normal_map>
              <roughness_map>
                model://tailsitter/materials/textures/metal_graphite/metal_graphite_roughness.jpg</roughness_map>
              <roughness>1.0</roughness>
              <metalness>1.0</metalness>
            </metal>
          </pbr>
        </material>
      </visual>
    </link>
    <joint name='rotor_1_joint' type='revolute'>
      <pose relative_to="base_link">-0.015 0.32 0.32 0 1.5708 0</pose>
      <child>rotor_1_link</child>
      <parent>base_link</parent>
      <axis>
        <xyz>0 0 1</xyz>
        <limit>
          <lower>-1e+16</lower>
          <upper>1e+16</upper>
        </limit>
        <dynamics>
          <damping>0.004</damping>
        </dynamics>
      </axis>
    </joint>

    <!-- CW -->
    <link name="rotor_2_link">
      <pose relative_to="rotor_2_joint">0 0 0 0 0 0</pose>
      <inertial>
        <pose>0 0 0 0 0 0</pose>
        <mass>0.025</mass>
        <inertia>
          <ixx>0.000130417</ixx>
          <ixy>0</ixy>
          <ixz>0</ixz>
          <iyy>0.000130417</iyy>
          <iyz>0</iyz>
          <izz>0.000260417</izz>
        </inertia>
      </inertial>
      <collision name="motor_collision">
        <geometry>
          <cylinder>
            <length>0.0178</length>
            <radius>0.0112</radius>
          </cylinder>
        </geometry>
      </collision>
      <collision name="prop_collision">
        <pose>0 0 0.022 0 0 0</pose>
        <geometry>
          <cylinder>
            <length>0.005</length>
            <radius>0.13</radius>
          </cylinder>
        </geometry>
      </collision>
      <visual name="motor_visual">
        <pose>0 0 -0.008 0 -1.5707963 0</pose>
        <geometry>
          <mesh>
            <uri>model://tailsitter/meshes/tailsitter_motor.dae</uri>
          </mesh>
        </geometry>
        <material>
          <ambient>1 1 1</ambient>
          <diffuse>1 1 1</diffuse>
          <specular>1 1 1</specular>
          <pbr>
            <metal>
              <albedo_map>
                model://tailsitter/materials/textures/blue_metal/blue_metal_basecolor.jpg</albedo_map>
              <metalness_map>
                model://tailsitter/materials/textures/blue_metal/blue_metal_metallic.jpg</metalness_map>
              <normal_map>model://tailsitter/materials/textures/blue_metal/blue_metal_normal.jpg</normal_map>
              <roughness_map>
                model://tailsitter/materials/textures/blue_metal/blue_metal_roughness.jpg</roughness_map>
              <roughness>1.0</roughness>
              <metalness>1.0</metalness>
            </metal>
          </pbr>
        </material>
      </visual>
      <visual name='prop_visual'>
        <pose>0 0 0.015 0 0 0</pose>
        <geometry>
          <mesh>
            <scale>1 1 1</scale>
            <uri>model://tailsitter/meshes/iris_prop_cw.dae</uri>
          </mesh>
        </geometry>
        <material>
          <diffuse>1.0 1.0 1.0</diffuse>
          <specular>1.0 1.0 1.0</specular>
          <pbr>
            <metal>
              <albedo_map>
                model://tailsitter/materials/textures/metal_graphite/metal_graphite_basecolor.jpg</albedo_map>
              <metalness_map>
                model://tailsitter/materials/textures/metal_graphite/metal_graphite_metallic.jpg</metalness_map>
              <normal_map>
                model://tailsitter/materials/textures/metal_graphite/metal_graphite_normal.jpg</normal_map>
              <roughness_map>
                model://tailsitter/materials/textures/metal_graphite/metal_graphite_roughness.jpg</roughness_map>
              <roughness>1.0</roughness>
              <metalness>1.0</metalness>
            </metal>
          </pbr>
        </material>
      </visual>
    </link>
    <joint name='rotor_2_joint' type='revolute'>
      <pose relative_to="base_link">-0.015 0.32 -0.32 0 1.5708 0</pose>
      <child>rotor_2_link</child>
      <parent>base_link</parent>
      <axis>
        <xyz>0 0 1</xyz>
        <limit>
          <lower>-1e+16</lower>
          <upper>1e+16</upper>
        </limit>
        <dynamics>
          <damping>0.004</damping>
        </dynamics>
      </axis>
    </joint>

    <!-- CW -->
    <link name="rotor_3_link">
      <pose relative_to="rotor_3_joint">0 0 0 0 0 0</pose>
      <inertial>
        <pose>0 0 0 0 0 0</pose>
        <mass>0.025</mass>
        <inertia>
          <ixx>0.000130417</ixx>
          <ixy>0</ixy>
          <ixz>0</ixz>
          <iyy>0.000130417</iyy>
          <iyz>0</iyz>
          <izz>0.000260417</izz>
        </inertia>
      </inertial>
      <collision name="motor_collision">
        <geometry>
          <cylinder>
            <length>0.0178</length>
            <radius>0.0112</radius>
          </cylinder>
        </geometry>
      </collision>
      <collision name="prop_collision">
        <pose>0 0 0.022 0 0 0</pose>
        <geometry>
          <cylinder>
            <length>0.005</length>
            <radius>0.13</radius>
          </cylinder>
        </geometry>
      </collision>
      <visual name="motor_visual">
        <pose>0 0 -0.008 0 -1.5707963 0</pose>
        <geometry>
          <mesh>
            <uri>model://tailsitter/meshes/tailsitter_motor.dae</uri>
          </mesh>
        </geometry>
        <material>
          <ambient>1 1 1</ambient>
          <diffuse>1 1 1</diffuse>
          <specular>1 1 1</specular>
          <pbr>
            <metal>
              <albedo_map>
                model://tailsitter/materials/textures/blue_metal/blue_metal_basecolor.jpg</albedo_map>
              <metalness_map>
                model://tailsitter/materials/textures/blue_metal/blue_metal_metallic.jpg</metalness_map>
              <normal_map>model://tailsitter/materials/textures/blue_metal/blue_metal_normal.jpg</normal_map>
              <roughness_map>
                model://tailsitter/materials/textures/blue_metal/blue_metal_roughness.jpg</roughness_map>
              <roughness>1.0</roughness>
              <metalness>1.0</metalness>
            </metal>
          </pbr>
        </material>
      </visual>
      <visual name='prop_visual'>
        <pose>0 0 0.015 0 0 0</pose>
        <geometry>
          <mesh>
            <scale>1 1 1</scale>
            <uri>model://tailsitter/meshes/iris_prop_cw.dae</uri>
          </mesh>
        </geometry>
        <material>
          <diffuse>1.0 1.0 1.0</diffuse>
          <specular>1.0 1.0 1.0</specular>
          <pbr>
            <metal>
              <albedo_map>
                model://tailsitter/materials/textures/metal_graphite/metal_graphite_basecolor.jpg</albedo_map>
              <metalness_map>
                model://tailsitter/materials/textures/metal_graphite/metal_graphite_metallic.jpg</metalness_map>
              <normal_map>
                model://tailsitter/materials/textures/metal_graphite/metal_graphite_normal.jpg</normal_map>
              <roughness_map>
                model://tailsitter/materials/textures/metal_graphite/metal_graphite_roughness.jpg</roughness_map>
              <roughness>1.0</roughness>
              <metalness>1.0</metalness>
            </metal>
          </pbr>
        </material>
      </visual>
    </link>
    <joint name='rotor_3_joint' type='revolute'>
      <pose relative_to="base_link">-0.015 -0.32 0.32 0 1.5708 0</pose>
      <child>rotor_3_link</child>
      <parent>base_link</parent>
      <axis>
        <xyz>0 0 1</xyz>
        <limit>
          <lower>-1e+16</lower>
          <upper>1e+16</upper>
        </limit>
        <dynamics>
          <damping>0.004</damping>
        </dynamics>
      </axis>
    </joint>


    <plugin filename="gz-sim-multicopter-motor-model-system" name="gz::sim::systems::MulticopterMotorModel">
      <jointName>rotor_0_joint</jointName>
      <linkName>rotor_0_link</linkName>
      <turningDirection>ccw</turningDirection>
      <timeConstantUp>0.0125</timeConstantUp>
      <timeConstantDown>0.025</timeConstantDown>
      <maxRotVelocity>2000.0</maxRotVelocity>
      <motorConstant>8.54858e-06</motorConstant>
      <momentConstant>0.032</momentConstant>
      <commandSubTopic>command/motor_speed</commandSubTopic>
      <motorNumber>0</motorNumber>
      <rotorDragCoefficient>8.06428e-05</rotorDragCoefficient>
      <rollingMomentCoefficient>1e-06</rollingMomentCoefficient>
      <rotorVelocitySlowdownSim>10</rotorVelocitySlowdownSim>
      <motorType>velocity</motorType>
    </plugin>

    <plugin filename="gz-sim-multicopter-motor-model-system" name="gz::sim::systems::MulticopterMotorModel">
      <jointName>rotor_1_joint</jointName>
      <linkName>rotor_1_link</linkName>
      <turningDirection>ccw</turningDirection>
      <timeConstantUp>0.0125</timeConstantUp>
      <timeConstantDown>0.025</timeConstantDown>
      <maxRotVelocity>2000.0</maxRotVelocity>
      <motorConstant>8.54858e-06</motorConstant>
      <momentConstant>0.032</momentConstant>
      <commandSubTopic>command/motor_speed</commandSubTopic>
      <motorNumber>1</motorNumber>
      <rotorDragCoefficient>8.06428e-05</rotorDragCoefficient>
      <rollingMomentCoefficient>1e-06</rollingMomentCoefficient>
      <rotorVelocitySlowdownSim>10</rotorVelocitySlowdownSim>
      <motorType>velocity</motorType>
    </plugin>

    <plugin filename="gz-sim-multicopter-motor-model-system" name="gz::sim::systems::MulticopterMotorModel">
      <jointName>rotor_2_joint</jointName>
      <linkName>rotor_2_link</linkName>
      <turningDirection>cw</turningDirection>
      <timeConstantUp>0.0125</timeConstantUp>
      <timeConstantDown>0.025</timeConstantDown>
      <maxRotVelocity>2000.0</maxRotVelocity>
      <motorConstant>8.54858e-06</motorConstant>
      <momentConstant>0.032</momentConstant>
      <commandSubTopic>command/motor_speed</commandSubTopic>
      <motorNumber>2</motorNumber>
      <rotorDragCoefficient>8.06428e-05</rotorDragCoefficient>
      <rollingMomentCoefficient>1e-06</rollingMomentCoefficient>
      <rotorVelocitySlowdownSim>10</rotorVelocitySlowdownSim>
      <motorType>velocity</motorType>
    </plugin>

    <plugin filename="gz-sim-multicopter-motor-model-system" name="gz::sim::systems::MulticopterMotorModel">
      <jointName>rotor_3_joint</jointName>
      <linkName>rotor_3_link</linkName>
      <turningDirection>cw</turningDirection>
      <timeConstantUp>0.0125</timeConstantUp>
      <timeConstantDown>0.025</timeConstantDown>
      <maxRotVelocity>2000.0</maxRotVelocity>
      <motorConstant>8.54858e-06</motorConstant>
      <momentConstant>0.032</momentConstant>
      <commandSubTopic>command/motor_speed</commandSubTopic>
      <motorNumber>3</motorNumber>
      <rotorDragCoefficient>8.06428e-05</rotorDragCoefficient>
      <rollingMomentCoefficient>1e-06</rollingMomentCoefficient>
      <rotorVelocitySlowdownSim>10</rotorVelocitySlowdownSim>
      <motorType>velocity</motorType>
    </plugin>

    <plugin filename="libWindEffectsPlugin" name="gz::sim::systems::WindEffects">
      <linkName>base_link</linkName>
    </plugin>

    <plugin filename="libAerodynamicsPlugin" name="gz::sim::systems::AerodynamicsPlugin">
      <link_name>base_link</link_name>
      <area>0.24</area>
      <air_density>1.17</air_density>
      <topic_force>zhang_force</topic_force>
      <topic_moment>zhang_moment</topic_moment>
      <if_omit_moment>false</if_omit_moment>
      <if_omit_force>false</if_omit_force>
      <!-- aero_id: specifies which aerodynamics model to use -->
      <!-- 0 for PHI aerodynamics -->
      <!-- 1 for BSPLINE aerodynamics -->
      <!-- 2 for LYU aerodynamics (not implemented) -->
      <!-- 3 for Adavanced Lift Drag plugin -->
      <aero_id>2</aero_id>
    </plugin>
  </model>
</sdf>
